Workbook
Name alfa: Resumo!$C$26

Sheet Resumo
B2: ThermoPlex S.A. – M&V do retrofit (PEE/ANEEL): resumo dos resultados
B3: Todos os valores abaixo são fórmulas ligadas às abas de cálculo (nenhum número digitado); as escolhas (variável mais correlacionada, variáveis mantidas) são decididas por fórmula.
B5: Resultado | C5: Valor | D5: Aba de origem
B6: Variável mais correlacionada com EE (maior |r|) | C6: =INDEX('4.1a Correlação'!$D$5:$J$5,MATCH(MAX('4.1a Correlação'!$E$17:$E$23),'4.1a Correlação'!$E$17:$E$23,0)) -> Temp | D6: 4.1a
B7: r de Pearson dessa variável com EE | C7: =INDEX('4.1a Correlação'!$C$17:$C$23,MATCH(MAX('4.1a Correlação'!$E$17:$E$23),'4.1a Correlação'!$E$17:$E$23,0)) -> 0.85872084 | D7: 4.1a
B8: Variáveis mantidas após a eliminação (p < α) | C8: ='4.2b Filtragem'!C115 -> P1, P2, Temp | D8: 4.2b
B9: Parcela da UR explicada pela Temp (R² de UR ~ Temp) | C9: ='4.1d Dependência Temp-UR'!C9 -> 0.8564993 | D9: 4.1d
B10: p-valor da parte da UR não explicada pela Temp (UR⊥) | C10: ='4.1d Dependência Temp-UR'!C19 -> 0.33938724 | D10: 4.1d
B11: Intercepto β0 (MWh/sem) | C11: ='4.2c Modelo Final'!$C$7 -> 111.00555 | D11: 4.2c
B12: β1 – P1 (MWh por mil unid.) | C12: ='4.2c Modelo Final'!$C$8 -> 2.6082654 | D12: 4.2c
B13: β2 – P2 (MWh por mil unid.) | C13: ='4.2c Modelo Final'!$C$9 -> 1.4109802 | D13: 4.2c
B14: β3 – Temp (MWh/°C) | C14: ='4.2c Modelo Final'!$C$10 -> 1.7383993 | D14: 4.2c
B15: R² do modelo final | C15: ='4.2c Modelo Final'!C13 -> 0.95131221 | D15: 4.2c
B16: R² ajustado | C16: ='4.2c Modelo Final'!C14 -> 0.94826922 | D16: 4.2c
B17: CV(RMSE) | C17: ='4.2c Modelo Final'!C20 -> 0.013264461 | D17: 4.2c
B18: Atende R² > 0,75 e CV(RMSE) < 15 %? | C18: =IF(AND('4.2c Modelo Final'!E27="ATENDE",'4.2c Modelo Final'!E28="ATENDE"),"SIM","NÃO") -> SIM | D18: 4.2c
B19: Economia evitada Ano 1 (MWh) | C19: ='4.3 Economia Evitada'!E8 -> 2883.4087 | D19: 4.3
B20: Redução vs. LB ajustada | C20: ='4.3 Economia Evitada'!E9 -> 0.21171632 | D20: 4.3
B21: Economia com cenário da extrusora, SEM ANR (MWh) | C21: ='4.4 ANR'!G6 -> 2538.4087 | D21: 4.4
B22: Economia com cenário da extrusora, COM ANR (MWh) | C22: ='4.4 ANR'!G7 -> 2883.4087 | D22: 4.4
B23: Redução COM ANR | C23: ='4.4 ANR'!G10 -> 0.20648565 | D23: 4.4
B25: Premissa (editável) | C25: Valor | D25: Usada em
B26: Nível de significância α (testes de hipótese e IC) | C26: 0.05 | D26: 4.1a, 4.1b, 4.1d, 4.2a, 4.2b, 4.2c

Sheet Ano 0 - Linha de Base
B2: ThermoPlex S.A. — Dados da Linha de Base (Ano 0)
B3: Série temporal de 52 semanas para modelagem da curva de carga e determinação do consumo de referência.
B5: Semana | C5: Consumo EE (MWh) | D5: P1 (mil unid) | E5: P2 (mil unid) | F5: P3 (mil unid) | G5: P4 (mil unid) | H5: P5 (mil unid) | I5: Temp Amb (°C) | J5: Umidade Rel (%)
B6: 1 | C6: 277 | D6: 24 | E6: 37.4 | F6: 85.7 | G6: 12.2 | H6: 157.4 | I6: 29.9 | J6: 0.694
B7: 2 | C7: 288.8 | D7: 28 | E7: 39.3 | F7: 85.7 | G7: 11.1 | H7: 145.9 | I7: 29.7 | J7: 0.709
B8: 3 | C8: 275.7 | D8: 25.2 | E8: 32.2 | F8: 87.9 | G8: 11.7 | H8: 154.4 | I8: 30.5 | J8: 0.763
B9: 4 | C9: 279.6 | D9: 26.6 | E9: 36.9 | F9: 82.1 | G9: 11.5 | H9: 145.5 | I9: 31.2 | J9: 0.72
B10: 5 | C10: 281.4 | D10: 26.6 | E10: 38.4 | F10: 85.1 | G10: 11.6 | H10: 161.5 | I10: 29.8 | J10: 0.705
B11: 6 | C11: 286.4 | D11: 26.2 | E11: 36 | F11: 80.6 | G11: 10.7 | H11: 159 | I11: 29.6 | J11: 0.693
B12: 7 | C12: 292.2 | D12: 24.4 | E12: 42.1 | F12: 83.5 | G12: 11.5 | H12: 143 | I12: 30.8 | J12: 0.652
B13: 8 | C13: 280.5 | D13: 26.2 | E13: 35.1 | F13: 81.4 | G13: 12 | H13: 152.8 | I13: 29.8 | J13: 0.697
B14: 9 | C14: 275.1 | D14: 23.2 | E14: 36.9 | F14: 82.4 | G14: 13 | H14: 150.2 | I14: 28.3 | J14: 0.681
B15: 10 | C15: 277 | D15: 23.7 | E15: 37.9 | F15: 84.7 | G15: 12.5 | H15: 155.9 | I15: 28.5 | J15: 0.756
B16: 11 | C16: 284.1 | D16: 22.8 | E16: 40.4 | F16: 78.3 | G16: 13.7 | H16: 137.3 | I16: 27.1 | J16: 0.659
B17: 12 | C17: 269.5 | D17: 23.2 | E17: 33.7 | F17: 91.4 | G17: 10.7 | H17: 150.5 | I17: 26.4 | J17: 0.666
... B57: 52 | C57: 284.3 | D57: 23.9 | E57: 41.9 | F57: 83.8 | G57: 10.8 | H57: 151.1 | I57: 28.8 | J57: 0.664
B59: TOTAL ANUAL | C59: =SUM(C6:C57) -> 13548 | D59: =SUM(D6:D57) -> 1182.4 | E59: =SUM(E6:E57) -> 1894.6 | F59: =SUM(F6:F57) -> 4276 | G59: =SUM(G6:G57) -> 600.6 | H59: =SUM(H6:H57) -> 7539.4
B61: MÉDIA SEMANAL | C61: =AVERAGE(C6:C57) -> 260.53846 | D61: =AVERAGE(D6:D57) -> 22.738462 | E61: =AVERAGE(E6:E57) -> 36.434615 | F61: =AVERAGE(F6:F57) -> 82.230769 | G61: =AVERAGE(G6:G57) -> 11.55 | H61: =AVERAGE(H6:H57) -> 144.98846 | I61: =AVERAGE(I6:I57) -> 22.328846 | J61: =AVERAGE(J6:J57) -> 0.60861538
B63: MÍNIMO | C63: =MIN(C6:C57) -> 234.2 | D63: =MIN(D6:D57) -> 17.4 | E63: =MIN(E6:E57) -> 29.2 | F63: =MIN(F6:F57) -> 75.5 | G63: =MIN(G6:G57) -> 9.4 | H63: =MIN(H6:H57) -> 128.5 | I63: =MIN(I6:I57) -> 14.6 | J63: =MIN(J6:J57) -> 0.48
B64: MÁXIMO | C64: =MAX(C6:C57) -> 292.2 | D64: =MAX(D6:D57) -> 28 | E64: =MAX(E6:E57) -> 42.1 | F64: =MAX(F6:F57) -> 91.4 | G64: =MAX(G6:G57) -> 13.7 | H64: =MAX(H6:H57) -> 161.5 | I64: =MAX(I6:I57) -> 31.2 | J64: =MAX(J6:J57) -> 0.763

Sheet Ano 1 - Pós-AEE
B2: ThermoPlex S.A. — Período de Determinação Pós-AEE (Ano 1)
B3: Medições reais de consumo elétrico pós-projeto e cálculo do Consumo Evitado via Linha de Base Ajustada.
B5: Semana | C5: Consumo Medido (MWh) | D5: P1 (mil unid) | E5: P2 (mil unid) | F5: P3 (mil unid) | G5: P4 (mil unid) | H5: P5 (mil unid) | I5: Temp Amb (°C) | J5: Umidade Rel (%) | K5: LB Ajustada (MWh) | L5: Economia (MWh) | M5: Economia (%)
B6: 1 | C6: 214.8 | D6: 20.7 | E6: 40.5 | F6: 89.7 | G6: 10.8 | H6: 144 | I6: 28.9 | J6: 0.747 | K6: ='4.2c Modelo Final'!$C$7+'4.2c Modelo Final'!$C$8*D6+'4.2c Modelo Final'!$C$9*E6+'4.2c Modelo Final'!$C$10*I6 -> 272.38108 | L6: =K6-C6 -> 57.58108 | M6: =L6/K6 -> 0.21139897
B7: 2 | C7: 219.6 | D7: 24.9 | E7: 39.3 | F7: 80.9 | G7: 13.4 | H7: 142.2 | I7: 30.3 | J7: 0.719 | K7: ='4.2c Modelo Final'!$C$7+'4.2c Modelo Final'!$C$8*D7+'4.2c Modelo Final'!$C$9*E7+'4.2c Modelo Final'!$C$10*I7 -> 284.07638 | L7: =K7-C7 -> 64.476377 | M7: =L7/K7 -> 0.22696846
B8: 3 | C8: 224.1 | D8: 23.3 | E8: 41.4 | F8: 78.8 | G8: 12.6 | H8: 149.5 | I8: 30.9 | J8: 0.673 | K8: ='4.2c Modelo Final'!$C$7+'4.2c Modelo Final'!$C$8*D8+'4.2c Modelo Final'!$C$9*E8+'4.2c Modelo Final'!$C$10*I8 -> 283.90925 | L8: =K8-C8 -> 59.80925 | M8: =L8/K8 -> 0.21066327
B9: 4 | C9: 223.2 | D9: 25.8 | E9: 34.8 | F9: 82.5 | G9: 12.9 | H9: 140.7 | I9: 30.8 | J9: 0.731 | K9: ='4.2c Modelo Final'!$C$7+'4.2c Modelo Final'!$C$8*D9+'4.2c Modelo Final'!$C$9*E9+'4.2c Modelo Final'!$C$10*I9 -> 280.9436 | L9: =K9-C9 -> 57.743605 | M9: =L9/K9 -> 0.2055345
B10: 5 | C10: 221.7 | D10: 23.8 | E10: 39.8 | F10: 83.2 | G10: 12.4 | H10: 151.1 | I10: 29.2 | J10: 0.659 | K10: ='4.2c Modelo Final'!$C$7+'4.2c Modelo Final'!$C$8*D10+'4.2c Modelo Final'!$C$9*E10+'4.2c Modelo Final'!$C$10*I10 -> 280.00054 | L10: =K10-C10 -> 58.300536 | M10: =L10/K10 -> 0.2082158
B11: 6 | C11: 221.1 | D11: 22.1 | E11: 40.7 | F11: 87.6 | G11: 10.8 | H11: 135.2 | I11: 29.5 | J11: 0.719 | K11: ='4.2c Modelo Final'!$C$7+'4.2c Modelo Final'!$C$8*D11+'4.2c Modelo Final'!$C$9*E11+'4.2c Modelo Final'!$C$10*I11 -> 277.35789 | L11: =K11-C11 -> 56.257887 | M11: =L11/K11 -> 0.202835
B12: 7 | C12: 216.7 | D12: 22.4 | E12: 35.8 | F12: 75.9 | G12: 11.3 | H12: 155.7 | I12: 29.8 | J12: 0.735 | K12: ='4.2c Modelo Final'!$C$7+'4.2c Modelo Final'!$C$8*D12+'4.2c Modelo Final'!$C$9*E12+'4.2c Modelo Final'!$C$10*I12 -> 271.74808 | L12: =K12-C12 -> 55.048083 | M12: =L12/K12 -> 0.20257027
B13: 8 | C13: 226.2 | D13: 25.1 | E13: 41 | F13: 89.4 | G13: 12.2 | H13: 151.5 | I13: 30 | J13: 0.674 | K13: ='4.2c Modelo Final'!$C$7+'4.2c Modelo Final'!$C$8*D13+'4.2c Modelo Final'!$C$9*E13+'4.2c Modelo Final'!$C$10*I13 -> 286.47518 | L13: =K13-C13 -> 60.275177 | M13: =L13/K13 -> 0.21040279
B14: 9 | C14: 220.7 | D14: 25.3 | E14: 39 | F14: 82.3 | G14: 10.7 | H14: 149.9 | I14: 28.2 | J14: 0.709 | K14: ='4.2c Modelo Final'!$C$7+'4.2c Modelo Final'!$C$8*D14+'4.2c Modelo Final'!$C$9*E14+'4.2c Modelo Final'!$C$10*I14 -> 281.04575 | L14: =K14-C14 -> 60.345751 | M14: =L14/K14 -> 0.2147186
B15: 10 | C15: 209.3 | D15: 22.9 | E15: 37.1 | F15: 81.2 | G15: 12.4 | H15: 155.4 | I15: 27.9 | J15: 0.688 | K15: ='4.2c Modelo Final'!$C$7+'4.2c Modelo Final'!$C$8*D15+'4.2c Modelo Final'!$C$9*E15+'4.2c Modelo Final'!$C$10*I15 -> 271.58353 | L15: =K15-C15 -> 62.283531 | M15: =L15/K15 -> 0.22933471
B16: 11 | C16: 219.3 | D16: 25.1 | E16: 39 | F16: 78.7 | G16: 11.6 | H16: 160.5 | I16: 26.5 | J16: 0.684 | K16: ='4.2c Modelo Final'!$C$7+'4.2c Modelo Final'!$C$8*D16+'4.2c Modelo Final'!$C$9*E16+'4.2c Modelo Final'!$C$10*I16 -> 277.56882 | L16: =K16-C16 -> 58.268819 | M16: =L16/K16 -> 0.20992566
B17: 12 | C17: 211.9 | D17: 20.7 | E17: 42.1 | F17: 76 | G17: 11.5 | H17: 155.6 | I17: 25.7 | J17: 0.709 | K17: ='4.2c Modelo Final'!$C$7+'4.2c Modelo Final'!$C$8*D17+'4.2c Modelo Final'!$C$9*E17+'4.2c Modelo Final'!$C$10*I17 -> 269.07577 | L17: =K17-C17 -> 57.17577 | M17: =L17/K17 -> 0.21248948
... B57: 52 | C57: 223 | D57: 25.8 | E57: 42.6 | F57: 79.7 | G57: 12.1 | H57: 152.7 | I57: 28.4 | J57: 0.697 | K57: ='4.2c Modelo Final'!$C$7+'4.2c Modelo Final'!$C$8*D57+'4.2c Modelo Final'!$C$9*E57+'4.2c Modelo Final'!$C$10*I57 -> 287.77709 | L57: =K57-C57 -> 64.777092 | M57: =L57/K57 -> 0.22509468
B59: TOTAL ANUAL | C59: =SUM(C6:C57) -> 10735.8 | D59: =SUM(D6:D57) -> 1178 | E59: =SUM(E6:E57) -> 1944.7 | F59: =SUM(F6:F57) -> 4277 | G59: =SUM(G6:G57) -> 612.9 | H59: =SUM(H6:H57) -> 7705.7 | I59: =SUM(I6:I57) -> 1168 | K59: =SUM(K6:K57) -> 13619.209 | L59: =SUM(L6:L57) -> 2883.4087 | M59: =L59/K59 -> 0.21171632
B60: MÉDIA SEMANAL | C60: =AVERAGE(C6:C57) -> 206.45769 | D60: =AVERAGE(D6:D57) -> 22.653846 | E60: =AVERAGE(E6:E57) -> 37.398077 | F60: =AVERAGE(F6:F57) -> 82.25 | G60: =AVERAGE(G6:G57) -> 11.786538 | H60: =AVERAGE(H6:H57) -> 148.18654 | I60: =AVERAGE(I6:I57) -> 22.461538 | J60: =AVERAGE(J6:J57) -> 0.61351923 | ... L60: =AVERAGE(L6:L57) -> 55.450167

Sheet 4.1a Correlação
B2: Questão 4.1.a – Matriz de Correlação de Pearson (Ano 0, n = 52 semanas)
B3: Memória de cálculo: r = CORREL(x; y) = Σ(x−x̄)(y−ȳ) / √[Σ(x−x̄)²·Σ(y−ȳ)²]. Varia de −1 a +1: o sinal dá o sentido da relação e o módulo, a intensidade linear. A matriz é simétrica e a diagonal vale 1 (cada variável com ela mesma); a coluna "EE (MWh)" mostra quais variáveis acompanham o consumo. Cores: azul = negativo, branco = 0, laranja = positivo.
C5: EE (MWh) | D5: P1 | E5: P2 | F5: P3 | G5: P4 | H5: P5 | I5: Temp | J5: UR
B6: EE (MWh) | C6: =CORREL('Ano 0 - Linha de Base'!$C$6:$C$57,'Ano 0 - Linha de Base'!$C$6:$C$57) -> 1 | D6: =CORREL('Ano 0 - Linha de Base'!$C$6:$C$57,'Ano 0 - Linha de Base'!$D$6:$D$57) -> 0.55701781 | E6: =CORREL('Ano 0 - Linha de Base'!$C$6:$C$57,'Ano 0 - Linha de Base'!$E$6:$E$57) -> 0.57092578 | F6: =CORREL('Ano 0 - Linha de Base'!$C$6:$C$57,'Ano 0 - Linha de Base'!$F$6:$F$57) -> 0.20679525 | G6: =CORREL('Ano 0 - Linha de Base'!$C$6:$C$57,'Ano 0 - Linha de Base'!$G$6:$G$57) -> 0.13346194 | H6: =CORREL('Ano 0 - Linha de Base'!$C$6:$C$57,'Ano 0 - Linha de Base'!$H$6:$H$57) -> 0.39758433 | I6: =CORREL('Ano 0 - Linha de Base'!$C$6:$C$57,'Ano 0 - Linha de Base'!$I$6:$I$57) -> 0.85872084 | J6: =CORREL('Ano 0 - Linha de Base'!$C$6:$C$57,'Ano 0 - Linha de Base'!$J$6:$J$57) -> 0.77670247
B7: P1 | C7: =CORREL('Ano 0 - Linha de Base'!$D$6:$D$57,'Ano 0 - Linha de Base'!$C$6:$C$57) -> 0.55701781 | D7: =CORREL('Ano 0 - Linha de Base'!$D$6:$D$57,'Ano 0 - Linha de Base'!$D$6:$D$57) -> 1 | E7: =CORREL('Ano 0 - Linha de Base'!$D$6:$D$57,'Ano 0 - Linha de Base'!$E$6:$E$57) -> -0.073621196 | F7: =CORREL('Ano 0 - Linha de Base'!$D$6:$D$57,'Ano 0 - Linha de Base'!$F$6:$F$57) -> 0.0050007446 | G7: =CORREL('Ano 0 - Linha de Base'!$D$6:$D$57,'Ano 0 - Linha de Base'!$G$6:$G$57) -> 0.17831777 | H7: =CORREL('Ano 0 - Linha de Base'!$D$6:$D$57,'Ano 0 - Linha de Base'!$H$6:$H$57) -> 0.34587918 | I7: =CORREL('Ano 0 - Linha de Base'!$D$6:$D$57,'Ano 0 - Linha de Base'!$I$6:$I$57) -> 0.18259319 | J7: =CORREL('Ano 0 - Linha de Base'!$D$6:$D$57,'Ano 0 - Linha de Base'!$J$6:$J$57) -> 0.19771357
B8: P2 | C8: =CORREL('Ano 0 - Linha de Base'!$E$6:$E$57,'Ano 0 - Linha de Base'!$C$6:$C$57) -> 0.57092578 | D8: =CORREL('Ano 0 - Linha de Base'!$E$6:$E$57,'Ano 0 - Linha de Base'!$D$6:$D$57) -> -0.073621196 | E8: =CORREL('Ano 0 - Linha de Base'!$E$6:$E$57,'Ano 0 - Linha de Base'!$E$6:$E$57) -> 1 | F8: =CORREL('Ano 0 - Linha de Base'!$E$6:$E$57,'Ano 0 - Linha de Base'!$F$6:$F$57) -> 0.033262428 | G8: =CORREL('Ano 0 - Linha de Base'!$E$6:$E$57,'Ano 0 - Linha de Base'!$G$6:$G$57) -> 0.025224161 | H8: =CORREL('Ano 0 - Linha de Base'!$E$6:$E$57,'Ano 0 - Linha de Base'!$H$6:$H$57) -> -0.010527242 | I8: =CORREL('Ano 0 - Linha de Base'!$E$6:$E$57,'Ano 0 - Linha de Base'!$I$6:$I$57) -> 0.53646054 | J8: =CORREL('Ano 0 - Linha de Base'!$E$6:$E$57,'Ano 0 - Linha de Base'!$J$6:$J$57) -> 0.42146534
B9: P3 | C9: =CORREL('Ano 0 - Linha de Base'!$F$6:$F$57,'Ano 0 - Linha de Base'!$C$6:$C$57) -> 0.20679525 | D9: =CORREL('Ano 0 - Linha de Base'!$F$6:$F$57,'Ano 0 - Linha de Base'!$D$6:$D$57) -> 0.0050007446 | E9: =CORREL('Ano 0 - Linha de Base'!$F$6:$F$57,'Ano 0 - Linha de Base'!$E$6:$E$57) -> 0.033262428 | F9: =CORREL('Ano 0 - Linha de Base'!$F$6:$F$57,'Ano 0 - Linha de Base'!$F$6:$F$57) -> 1 | G9: =CORREL('Ano 0 - Linha de Base'!$F$6:$F$57,'Ano 0 - Linha de Base'!$G$6:$G$57) -> 0.02879474 | H9: =CORREL('Ano 0 - Linha de Base'!$F$6:$F$57,'Ano 0 - Linha de Base'!$H$6:$H$57) -> 0.087427276 | I9: =CORREL('Ano 0 - Linha de Base'!$F$6:$F$57,'Ano 0 - Linha de Base'!$I$6:$I$57) -> 0.32238178 | J9: =CORREL('Ano 0 - Linha de Base'!$F$6:$F$57,'Ano 0 - Linha de Base'!$J$6:$J$57) -> 0.35209218
B10: P4 | C10: =CORREL('Ano 0 - Linha de Base'!$G$6:$G$57,'Ano 0 - Linha de Base'!$C$6:$C$57) -> 0.13346194 | D10: =CORREL('Ano 0 - Linha de Base'!$G$6:$G$57,'Ano 0 - Linha de Base'!$D$6:$D$57) -> 0.17831777 | E10: =CORREL('Ano 0 - Linha de Base'!$G$6:$G$57,'Ano 0 - Linha de Base'!$E$6:$E$57) -> 0.025224161 | F10: =CORREL('Ano 0 - Linha de Base'!$G$6:$G$57,'Ano 0 - Linha de Base'!$F$6:$F$57) -> 0.02879474 | G10: =CORREL('Ano 0 - Linha de Base'!$G$6:$G$57,'Ano 0 - Linha de Base'!$G$6:$G$57) -> 1 | H10: =CORREL('Ano 0 - Linha de Base'!$G$6:$G$57,'Ano 0 - Linha de Base'!$H$6:$H$57) -> 0.023927557 | I10: =CORREL('Ano 0 - Linha de Base'!$G$6:$G$57,'Ano 0 - Linha de Base'!$I$6:$I$57) -> 0.043637997 | J10: =CORREL('Ano 0 - Linha de Base'!$G$6:$G$57,'Ano 0 - Linha de Base'!$J$6:$J$57) -> 0.065028584
B11: P5 | C11: =CORREL('Ano 0 - Linha de Base'!$H$6:$H$57,'Ano 0 - Linha de Base'!$C$6:$C$57) -> 0.39758433 | D11: =CORREL('Ano 0 - Linha de Base'!$H$6:$H$57,'Ano 0 - Linha de Base'!$D$6:$D$57) -> 0.34587918 | E11: =CORREL('Ano 0 - Linha de Base'!$H$6:$H$57,'Ano 0 - Linha de Base'!$E$6:$E$57) -> -0.010527242 | F11: =CORREL('Ano 0 - Linha de Base'!$H$6:$H$57,'Ano 0 - Linha de Base'!$F$6:$F$57) -> 0.087427276 | G11: =CORREL('Ano 0 - Linha de Base'!$H$6:$H$57,'Ano 0 - Linha de Base'!$G$6:$G$57) -> 0.023927557 | H11: =CORREL('Ano 0 - Linha de Base'!$H$6:$H$57,'Ano 0 - Linha de Base'!$H$6:$H$57) -> 1 | I11: =CORREL('Ano 0 - Linha de Base'!$H$6:$H$57,'Ano 0 - Linha de Base'!$I$6:$I$57) -> 0.38487724 | J11: =CORREL('Ano 0 - Linha de Base'!$H$6:$H$57,'Ano 0 - Linha de Base'!$J$6:$J$57) -> 0.42115956
B12: Temp | C12: =CORREL('Ano 0 - Linha de Base'!$I$6:$I$57,'Ano 0 - Linha de Base'!$C$6:$C$57) -> 0.85872084 | D12: =CORREL('Ano 0 - Linha de Base'!$I$6:$I$57,'Ano 0 - Linha de Base'!$D$6:$D$57) -> 0.18259319 | E12: =CORREL('Ano 0 - Linha de Base'!$I$6:$I$57,'Ano 0 - Linha de Base'!$E$6:$E$57) -> 0.53646054 | F12: =CORREL('Ano 0 - Linha de Base'!$I$6:$I$57,'Ano 0 - Linha de Base'!$F$6:$F$57) -> 0.32238178 | G12: =CORREL('Ano 0 - Linha de Base'!$I$6:$I$57,'Ano 0 - Linha de Base'!$G$6:$G$57) -> 0.043637997 | H12: =CORREL('Ano 0 - Linha de Base'!$I$6:$I$57,'Ano 0 - Linha de Base'!$H$6:$H$57) -> 0.38487724 | I12: =CORREL('Ano 0 - Linha de Base'!$I$6:$I$57,'Ano 0 - Linha de Base'!$I$6:$I$57) -> 1 | J12: =CORREL('Ano 0 - Linha de Base'!$I$6:$I$57,'Ano 0 - Linha de Base'!$J$6:$J$57) -> 0.92547248
B13: UR | C13: =CORREL('Ano 0 - Linha de Base'!$J$6:$J$57,'Ano 0 - Linha de Base'!$C$6:$C$57) -> 0.77670247 | D13: =CORREL('Ano 0 - Linha de Base'!$J$6:$J$57,'Ano 0 - Linha de Base'!$D$6:$D$57) -> 0.19771357 | E13: =CORREL('Ano 0 - Linha de Base'!$J$6:$J$57,'Ano 0 - Linha de Base'!$E$6:$E$57) -> 0.42146534 | F13: =CORREL('Ano 0 - Linha de Base'!$J$6:$J$57,'Ano 0 - Linha de Base'!$F$6:$F$57) -> 0.35209218 | G13: =CORREL('Ano 0 - Linha de Base'!$J$6:$J$57,'Ano 0 - Linha de Base'!$G$6:$G$57) -> 0.065028584 | H13: =CORREL('Ano 0 - Linha de Base'!$J$6:$J$57,'Ano 0 - Linha de Base'!$H$6:$H$57) -> 0.42115956 | I13: =CORREL('Ano 0 - Linha de Base'!$J$6:$J$57,'Ano 0 - Linha de Base'!$I$6:$I$57) -> 0.92547248 | J13: =CORREL('Ano 0 - Linha de Base'!$J$6:$J$57,'Ano 0 - Linha de Base'!$J$6:$J$57) -> 1
B15: Correlação de EE com cada variável e teste de significância (H0: ρ = 0)
B16: Variável | C16: r (com EE) | D16: r² | E16: |r| | F16: t = r·√(n−2)/√(1−r²) | G16: p-valor | H16: Classe | I16: Significativa (p < α)? | J16: Ranking |r|
B17: P1 (mil unid) – Estrutural Pesada | C17: =C7 -> 0.55701781 | D17: =C17^2 -> 0.31026884 | E17: =ABS(C17) -> 0.55701781 | F17: =C17*SQRT(COUNT('Ano 0 - Linha de Base'!$C$6:$C$57)-2)/SQRT(1-C17^2) -> 4.7425745 | G17: =TDIST(ABS(F17),COUNT('Ano 0 - Linha de Base'!$C$6:$C$57)-2,2) -> 1.7965862e-05 | H17: =IF(E17>=$I$26,"Forte",IF(E17>=$I$27,"Moderada",IF(E17>=$I$28,"Fraca","Muito fraca"))) -> Moderada | I17: =IF(G17<alfa,"Sim","Não") -> Sim | J17: =RANK(E17,$E$17:$E$23) -> 4
B18: P2 (mil unid) – Média | C18: =C8 -> 0.57092578 | D18: =C18^2 -> 0.32595624 | E18: =ABS(C18) -> 0.57092578 | F18: =C18*SQRT(COUNT('Ano 0 - Linha de Base'!$C$6:$C$57)-2)/SQRT(1-C18^2) -> 4.917231 | G18: =TDIST(ABS(F18),COUNT('Ano 0 - Linha de Base'!$C$6:$C$57)-2,2) -> 9.8863841e-06 | H18: =IF(E18>=$I$26,"Forte",IF(E18>=$I$27,"Moderada",IF(E18>=$I$28,"Fraca","Muito fraca"))) -> Moderada | I18: =IF(G18<alfa,"Sim","Não") -> Sim | J18: =RANK(E18,$E$17:$E$23) -> 3
B19: P3 (mil unid) – Leve | C19: =C9 -> 0.20679525 | D19: =C19^2 -> 0.042764274 | E19: =ABS(C19) -> 0.20679525 | F19: =C19*SQRT(COUNT('Ano 0 - Linha de Base'!$C$6:$C$57)-2)/SQRT(1-C19^2) -> 1.4945695 | G19: =TDIST(ABS(F19),COUNT('Ano 0 - Linha de Base'!$C$6:$C$57)-2,2) -> 0.1413117 | H19: =IF(E19>=$I$26,"Forte",IF(E19>=$I$27,"Moderada",IF(E19>=$I$28,"Fraca","Muito fraca"))) -> Muito fraca | I19: =IF(G19<alfa,"Sim","Não") -> Não | J19: =RANK(E19,$E$17:$E$23) -> 6
B20: P4 (mil unid) – Inserções Poliméricas | C20: =C10 -> 0.13346194 | D20: =C20^2 -> 0.01781209 | E20: =ABS(C20) -> 0.13346194 | F20: =C20*SQRT(COUNT('Ano 0 - Linha de Base'!$C$6:$C$57)-2)/SQRT(1-C20^2) -> 0.95223722 | G20: =TDIST(ABS(F20),COUNT('Ano 0 - Linha de Base'!$C$6:$C$57)-2,2) -> 0.34555747 | H20: =IF(E20>=$I$26,"Forte",IF(E20>=$I$27,"Moderada",IF(E20>=$I$28,"Fraca","Muito fraca"))) -> Muito fraca | I20: =IF(G20<alfa,"Sim","Não") -> Não | J20: =RANK(E20,$E$17:$E$23) -> 7
B21: P5 (mil unid) – Acessórios | C21: =C11 -> 0.39758433 | D21: =C21^2 -> 0.1580733 | E21: =ABS(C21) -> 0.39758433 | F21: =C21*SQRT(COUNT('Ano 0 - Linha de Base'!$C$6:$C$57)-2)/SQRT(1-C21^2) -> 3.0639179 | G21: =TDIST(ABS(F21),COUNT('Ano 0 - Linha de Base'!$C$6:$C$57)-2,2) -> 0.0035150545 | H21: =IF(E21>=$I$26,"Forte",IF(E21>=$I$27,"Moderada",IF(E21>=$I$28,"Fraca","Muito fraca"))) -> Fraca | I21: =IF(G21<alfa,"Sim","Não") -> Sim | J21: =RANK(E21,$E$17:$E$23) -> 5
B22: Temp (°C) | C22: =C12 -> 0.85872084 | D22: =C22^2 -> 0.73740147 | E22: =ABS(C22) -> 0.85872084 | F22: =C22*SQRT(COUNT('Ano 0 - Linha de Base'!$C$6:$C$57)-2)/SQRT(1-C22^2) -> 11.84925 | G22: =TDIST(ABS(F22),COUNT('Ano 0 - Linha de Base'!$C$6:$C$57)-2,2) -> 3.9428642e-16 | H22: =IF(E22>=$I$26,"Forte",IF(E22>=$I$27,"Moderada",IF(E22>=$I$28,"Fraca","Muito fraca"))) -> Forte | I22: =IF(G22<alfa,"Sim","Não") -> Sim | J22: =RANK(E22,$E$17:$E$23) -> 1
B23: UR (fração) | C23: =C13 -> 0.77670247 | D23: =C23^2 -> 0.60326673 | E23: =ABS(C23) -> 0.77670247 | F23: =C23*SQRT(COUNT('Ano 0 - Linha de Base'!$C$6:$C$57)-2)/SQRT(1-C23^2) -> 8.7194758 | G23: =TDIST(ABS(F23),COUNT('Ano 0 - Linha de Base'!$C$6:$C$57)-2,2) -> 1.3096619e-11 | H23: =IF(E23>=$I$26,"Forte",IF(E23>=$I$27,"Moderada",IF(E23>=$I$28,"Fraca","Muito fraca"))) -> Forte | I23: =IF(G23<alfa,"Sim","Não") -> Sim | J23: =RANK(E23,$E$17:$E$23) -> 2
B25: Colinearidade entre regressores e limiares de classificação
B26: r(Temp, UR) | C26: =J12 -> 0.92547248 | F26: Limiar "Forte" (|r| ≥) | I26: 0.7
B27: r² (Temp, UR) | C27: =C26^2 -> 0.8564993 | F27: Limiar "Moderada" (|r| ≥) | I27: 0.5
B28: VIF par-a-par = 1/(1−r²) | C28: =1/(1-C27) -> 6.9686074 | F28: Limiar "Fraca" (|r| ≥) | I28: 0.3
B29: r crítico (bilateral, α do Resumo) | C29: =TINV(alfa,COUNT('Ano 0 - Linha de Base'!$C$6:$C$57)-2)/SQRT(COUNT('Ano 0 - Linha de Base'!$C$6:$C$57)-2+TINV(alfa,COUNT('Ano 0 - Linha de Base'!$C$6:$C$57)-2)^2) -> 0.27324348
B30: ="Leitura: a variável mais correlacionada com EE é "&INDEX($D$5:$J$5,MATCH(1,$J$17:$J$23,0))&" (r = "&FIXED(INDEX($C$17:$C$23,MATCH(1,$J$17:$J$23,0)),2,TRUE)&")"&", seguida por "&INDEX($D$5:$J$5,MATCH(2,$J$17:$J$23,0))&" (r = "&FIXED(INDEX($C$17:$C$23,MATCH(2,$J$17:$J$23,0)),2,TRUE)&")"&", "&INDEX($D$5:$J$5,MATCH(3,$J$17:$J$23,0))&" (r = "&FIXED(INDEX($C$17:$C$23,MATCH(3,$J$17:$J$23,0)),2,TRUE)&")"&" e "&INDEX($D$5:$J$5,MATCH(4,$J$17:$J$23,0))&" (r = "&FIXED(INDEX($C$17:$C$23,MATCH(4,$J$17:$J$23,0)),2,TRUE)&")"&". Com n = "&COUNT('Ano 0 - Linha de Base'!$C$6:$C$57)&" semanas, |r| > "&FIXED($C$29,2,TRUE)&" já é significativo ao nível α. Entre os regressores, Temp e UR têm r = "&FIXED($C$26,2,TRUE)&" (R² = "&FIXED($C$27,2,TRUE)&"): são redundantes e não devem entrar juntas no modelo." -> Leitura: a variável mais correlacionada com EE é Temp (r = 0,86), seguida por UR (r = 0,78), P2 (r = 0,57) e P1 (r = 0,56). Com n = 52 semanas, |r| > 0,27 já é significativo ao nível α. Entre os regressores, Temp e UR têm r = 0,93 (R² = 0,86): são redundantes e não devem entrar juntas no modelo.

Sheet 4.1b Seleção
B2: Questão 4.1.b – Variáveis com impacto direto no consumo (correlação + análise física do processo)
B3: Critério em 3 etapas, todas por fórmula: (1) correlação com EE é significativa? (4.1a); (2) o efeito persiste controlando as demais variáveis, isto é, p-valor parcial < α na regressão completa (4.2a)? (3) existe mecanismo físico relevante no processo (coluna "Peso físico", premissa de engenharia, em azul)? "Direto" = (2) e (3) atendidos. Se a correlação é alta mas o efeito parcial não é, e a variável é colinear com outra, o impacto é "Indireto".
B5: Variável | C5: r com EE (4.1a) | D5: Classe de |r| | E5: Correlação significativa? | F5: Maior |r| com outro regressor | G5: Colinear com | H5: p-valor parcial (4.2a) | I5: Peso físico no processo (premissa) | J5: Classificação | K5: Decisão | L5: Confirmada na eliminação (4.2b) | M5: Justificativa física
B6: P1 (mil unid) – Estrutural Pesada | C6: ='4.1a Correlação'!C17 -> 0.55701781 | D6: ='4.1a Correlação'!H17 -> Moderada | E6: ='4.1a Correlação'!I17 -> Sim | F6: =SUMPRODUCT(MAX(ABS('4.1a Correlação'!$D7:$J7)*(ABS('4.1a Correlação'!$D7:$J7)<0.9999))) -> 0.0050007446 | G6: =INDEX('4.1a Correlação'!$D$5:$J$5,MATCH(F6,INDEX(ABS('4.1a Correlação'!$D7:$J7)*(ABS('4.1a Correlação'!$D7:$J7)<0.9999),0),0)) -> P3 | H6: ='4.2a Regressão Completa'!F8 -> 2.628911e-16 | I6: Alto | J6: =IF(AND(I6<>"Baixo",H6<alfa),"Direto",IF(AND(E6="Sim",F6>='4.1a Correlação'!$I$26),"Indireto (via "&G6&")","Sem efeito próprio")) -> Direto | K6: =IF(J6="Direto","Manter","Descartar") -> Manter | L6: =IF(ISNUMBER(MATCH(INDEX('4.1a Correlação'!$D$5:$J$5,1),Aux_X!$T$6:$V$6,0)),"Sim","Não") -> Sim | M6: Peça pesada, processo térmico longo: maior massa × tempo de permanência no forno de cura ⇒ maior energia por unidade. Causalidade direta e coeficiente esperado positivo.
B7: P2 (mil unid) – Média | C7: ='4.1a Correlação'!C18 -> 0.57092578 | D7: ='4.1a Correlação'!H18 -> Moderada | E7: ='4.1a Correlação'!I18 -> Sim | F7: =SUMPRODUCT(MAX(ABS('4.1a Correlação'!$D8:$J8)*(ABS('4.1a Correlação'!$D8:$J8)<0.9999))) -> 0.033262428 | G7: =INDEX('4.1a Correlação'!$D$5:$J$5,MATCH(F7,INDEX(ABS('4.1a Correlação'!$D8:$J8)*(ABS('4.1a Correlação'!$D8:$J8)<0.9999),0),0)) -> P3 | H7: ='4.2a Regressão Completa'!F9 -> 3.0172276e-07 | I7: Médio | J7: =IF(AND(I7<>"Baixo",H7<alfa),"Direto",IF(AND(E7="Sim",F7>='4.1a Correlação'!$I$26),"Indireto (via "&G7&")","Sem efeito próprio")) -> Direto | K7: =IF(J7="Direto","Manter","Descartar") -> Manter | L7: =IF(ISNUMBER(MATCH(INDEX('4.1a Correlação'!$D$5:$J$5,2),Aux_X!$T$6:$V$6,0)),"Sim","Não") -> Sim | M7: Peça média, processo térmico médio: mesma lógica de P1, com menor energia unitária. Impacto direto.
B8: P3 (mil unid) – Leve | C8: ='4.1a Correlação'!C19 -> 0.20679525 | D8: ='4.1a Correlação'!H19 -> Muito fraca | E8: ='4.1a Correlação'!I19 -> Não | F8: =SUMPRODUCT(MAX(ABS('4.1a Correlação'!$D9:$J9)*(ABS('4.1a Correlação'!$D9:$J9)<0.9999))) -> 0 | G8: =INDEX('4.1a Correlação'!$D$5:$J$5,MATCH(F8,INDEX(ABS('4.1a Correlação'!$D9:$J9)*(ABS('4.1a Correlação'!$D9:$J9)<0.9999),0),0)) -> P3 | H8: ='4.2a Regressão Completa'!F10 -> 0.8683077 | I8: Baixo | J8: =IF(AND(I8<>"Baixo",H8<alfa),"Direto",IF(AND(E8="Sim",F8>='4.1a Correlação'!$I$26),"Indireto (via "&G8&")","Sem efeito próprio")) -> Sem efeito próprio | K8: =IF(J8="Direto","Manter","Descartar") -> Descartar | L8: =IF(ISNUMBER(MATCH(INDEX('4.1a Correlação'!$D$5:$J$5,3),Aux_X!$T$6:$V$6,0)),"Sim","Não") -> Não | M8: Moldagem rápida, peça leve: pouco tempo e pouca massa em forno; carga térmica desprezível frente ao total. Correlação fraca, sem efeito parcial.
B9: P4 (mil unid) – Inserções Poliméricas | C9: ='4.1a Correlação'!C20 -> 0.13346194 | D9: ='4.1a Correlação'!H20 -> Muito fraca | E9: ='4.1a Correlação'!I20 -> Não | F9: =SUMPRODUCT(MAX(ABS('4.1a Correlação'!$D10:$J10)*(ABS('4.1a Correlação'!$D10:$J10)<0.9999))) -> 0.02879474 | G9: =INDEX('4.1a Correlação'!$D$5:$J$5,MATCH(F9,INDEX(ABS('4.1a Correlação'!$D10:$J10)*(ABS('4.1a Correlação'!$D10:$J10)<0.9999),0),0)) -> P3 | H9: ='4.2a Regressão Completa'!F11 -> 0.5570755 | I9: Baixo | J9: =IF(AND(I9<>"Baixo",H9<alfa),"Direto",IF(AND(E9="Sim",F9>='4.1a Correlação'!$I$26),"Indireto (via "&G9&")","Sem efeito próprio")) -> Sem efeito próprio | K9: =IF(J9="Direto","Manter","Descartar") -> Descartar | L9: =IF(ISNUMBER(MATCH(INDEX('4.1a Correlação'!$D$5:$J$5,4),Aux_X!$T$6:$V$6,0)),"Sim","Não") -> Não | M9: Inserções poliméricas, volume baixo e variação pequena: energia marginal. Sem efeito parcial detectável.
B10: P5 (mil unid) – Acessórios | C10: ='4.1a Correlação'!C21 -> 0.39758433 | D10: ='4.1a Correlação'!H21 -> Fraca | E10: ='4.1a Correlação'!I21 -> Sim | F10: =SUMPRODUCT(MAX(ABS('4.1a Correlação'!$D11:$J11)*(ABS('4.1a Correlação'!$D11:$J11)<0.9999))) -> 0.087427276 | G10: =INDEX('4.1a Correlação'!$D$5:$J$5,MATCH(F10,INDEX(ABS('4.1a Correlação'!$D11:$J11)*(ABS('4.1a Correlação'!$D11:$J11)<0.9999),0),0)) -> P3 | H10: ='4.2a Regressão Completa'!F12 -> 0.9615518 | I10: Baixo | J10: =IF(AND(I10<>"Baixo",H10<alfa),"Direto",IF(AND(E10="Sim",F10>='4.1a Correlação'!$I$26),"Indireto (via "&G10&")","Sem efeito próprio")) -> Sem efeito próprio | K10: =IF(J10="Direto","Manter","Descartar") -> Descartar | L10: =IF(ISNUMBER(MATCH(INDEX('4.1a Correlação'!$D$5:$J$5,5),Aux_X!$T$6:$V$6,0)),"Sim","Não") -> Não | M10: Acessórios e pequenos componentes, volume alto mas energia unitária mínima. A correlação marginal (coluna C) vem de colinearidade com Temp e P1, não de causa direta.
B11: Temp (°C) | C11: ='4.1a Correlação'!C22 -> 0.85872084 | D11: ='4.1a Correlação'!H22 -> Forte | E11: ='4.1a Correlação'!I22 -> Sim | F11: =SUMPRODUCT(MAX(ABS('4.1a Correlação'!$D12:$J12)*(ABS('4.1a Correlação'!$D12:$J12)<0.9999))) -> 0.32238178 | G11: =INDEX('4.1a Correlação'!$D$5:$J$5,MATCH(F11,INDEX(ABS('4.1a Correlação'!$D12:$J12)*(ABS('4.1a Correlação'!$D12:$J12)<0.9999),0),0)) -> P3 | H11: ='4.2a Regressão Completa'!F13 -> 2.7719659e-09 | I11: Alto | J11: =IF(AND(I11<>"Baixo",H11<alfa),"Direto",IF(AND(E11="Sim",F11>='4.1a Correlação'!$I$26),"Indireto (via "&G11&")","Sem efeito próprio")) -> Direto | K11: =IF(J11="Direto","Manter","Descartar") -> Manter | L11: =IF(ISNUMBER(MATCH(INDEX('4.1a Correlação'!$D$5:$J$5,6),Aux_X!$T$6:$V$6,0)),"Sim","Não") -> Sim | M11: Carga térmica ambiente: perdas dos fornos, rejeição de calor e, sobretudo, carga de resfriamento/desumidificação das salas limpas. Variável climática dominante.
B12: UR (fração) | C12: ='4.1a Correlação'!C23 -> 0.77670247 | D12: ='4.1a Correlação'!H23 -> Forte | E12: ='4.1a Correlação'!I23 -> Sim | F12: =SUMPRODUCT(MAX(ABS('4.1a Correlação'!$D13:$J13)*(ABS('4.1a Correlação'!$D13:$J13)<0.9999))) -> 0.35209218 | G12: =INDEX('4.1a Correlação'!$D$5:$J$5,MATCH(F12,INDEX(ABS('4.1a Correlação'!$D13:$J13)*(ABS('4.1a Correlação'!$D13:$J13)<0.9999),0),0)) -> P3 | H12: ='4.2a Regressão Completa'!F14 -> 0.35017047 | I12: Médio | J12: =IF(AND(I12<>"Baixo",H12<alfa),"Direto",IF(AND(E12="Sim",F12>='4.1a Correlação'!$I$26),"Indireto (via "&G12&")","Sem efeito próprio")) -> Sem efeito próprio | K12: =IF(J12="Direto","Manter","Descartar") -> Descartar | L12: =IF(ISNUMBER(MATCH(INDEX('4.1a Correlação'!$D$5:$J$5,7),Aux_X!$T$6:$V$6,0)),"Sim","Não") -> Não | M12: Influencia a desumidificação, mas acompanha a temperatura (ver aba 4.1d): após controlar Temp, não acrescenta informação.
B14: ="Conclusão: impacto direto relevante em "&LEFT(IF(J6="Direto",LEFT(B6,FIND(" ",B6&" ")-1)&", ","")&IF(J7="Direto",LEFT(B7,FIND(" ",B7&" ")-1)&", ","")&IF(J8="Direto",LEFT(B8,FIND(" ",B8&" ")-1)&", ","")&IF(J9="Direto",LEFT(B9,FIND(" ",B9&" ")-1)&", ","")&IF(J10="Direto",LEFT(B10,FIND(" ",B10&" ")-1)&", ","")&IF(J11="Direto",LEFT(B11,FIND(" ",B11&" ")-1)&", ","")&IF(J12="Direto",LEFT(B12,FIND(" ",B12&" ")-1)&", ",""),LEN(IF(J6="Direto",LEFT(B6,FIND(" ",B6&" ")-1)&", ","")&IF(J7="Direto",LEFT(B7,FIND(" ",B7&" ")-1)&", ","")&IF(J8="Direto",LEFT(B8,FIND(" ",B8&" ")-1)&", ","")&IF(J9="Direto",LEFT(B9,FIND(" ",B9&" ")-1)&", ","")&IF(J10="Direto",LEFT(B10,FIND(" ",B10&" ")-1)&", ","")&IF(J11="Direto",LEFT(B11,FIND(" ",B11&" ")-1)&", ","")&IF(J12="Direto",LEFT(B12,FIND(" ",B12&" ")-1)&", ",""))-2)&"."&" Indiretas: "&COUNTIF(J6:J12,"Indireto*")&" variável(is) (acompanham outra, sem efeito parcial). Sem efeito próprio: "&COUNTIF(J6:J12,"Sem efeito próprio")&" variável(is). "&"Coerência com a eliminação regressiva (4.2b): "&IF(SUMPRODUCT((K6:K12="Manter")*(L6:L12="Não"))+SUMPRODUCT((K6:K12="Descartar")*(L6:L12="Sim"))=0,"todas as decisões conferem.","há divergência: revisar.") -> Conclusão: impacto direto relevante em P1, P2, Temp. Indiretas: 0 variável(is) (acompanham outra, sem efeito parcial). Sem efeito próprio: 4 variável(is). Coerência com a eliminação regressiva (4.2b): todas as decisões conferem.
B15: Limiar de colinearidade = limiar "Forte" de |r| da aba 4.1a (I26); α = nome definido "alfa" (Resumo).

Sheet 4.1c Parsimônia
B2: Questão 4.1.c – Princípio da Parsimônia e graus de liberdade
B3: Comparação numérica entre o modelo com 7 variáveis (M1) e o modelo final (M5).
B5: Indicador | C5: M1 (7 variáveis) | D5: M5 (3 variáveis) | E5: Comentário
B6: Nº de observações (n) | C6: =COUNT('Ano 0 - Linha de Base'!$C$6:$C$57) -> 52 | D6: =COUNT('Ano 0 - Linha de Base'!$C$6:$C$57) -> 52 | E6: Mesmo conjunto de semanas do Ano 0.
B7: Nº de variáveis explicativas (k) | C7: =COUNTA('4.2a Regressão Completa'!B8:B14) -> 7 | D7: =COUNTA('4.2c Modelo Final'!B8:B10) -> 3 | E7: k = nº de coeficientes angulares (sem o intercepto).
B8: Graus de liberdade residuais (n−k−1) | C8: ='4.2a Regressão Completa'!C21 -> 44 | D8: ='4.2c Modelo Final'!C17 -> 48 | E8: Cada variável a mais consome 1 gl que seria usado para estimar a variância do erro.
B9: Observações por parâmetro (n/(k+1)) | C9: =C6/(C7+1) -> 6.5 | D9: =D6/(D7+1) -> 13 | E9: Regra prática: ≥ 10 observações por parâmetro; quanto menor a razão, mais incerto o ajuste.
B10: R² | C10: ='4.2a Regressão Completa'!C17 -> 0.95266178 | D10: ='4.2c Modelo Final'!C13 -> 0.95131221 | E10: R² de M1 é maior só por construção (nunca diminui ao incluir variáveis).
B11: R² ajustado | C11: ='4.2a Regressão Completa'!C18 -> 0.9451307 | D11: ='4.2c Modelo Final'!C14 -> 0.94826922 | E11: Penaliza complexidade: M5 é melhor que M1.
B12: RMSE (MWh) | C12: ='4.2a Regressão Completa'!C19 -> 3.5591938 | D12: ='4.2c Modelo Final'!C15 -> 3.4559023 | E12: Praticamente iguais: as variáveis retiradas não explicam nada a mais.
B13: Maior p-valor entre as variáveis | C13: =MAX('4.2a Regressão Completa'!F8:F14) -> 0.9615518 | D13: =MAX('4.2c Modelo Final'!F8:F10) -> 1.0688158e-08 | E13: M1 contém variáveis não significativas (p≫0,05).
B14: Erro-padrão do coeficiente de Temp | C14: ='4.2a Regressão Completa'!D13 -> 0.26612698 | D14: ='4.2c Modelo Final'!D10 -> 0.10764499 | E14: Em M1, a colinearidade com UR infla a incerteza do coeficiente de Temp.
B15: Erro-padrão do coeficiente de UR / Temp (M1) | C15: ='4.2a Regressão Completa'!D14 -> 18.12188 | D15: — | E15: =IF(C15>ABS('4.2a Regressão Completa'!C14),"O erro-padrão de UR é maior que o módulo do próprio coeficiente (|t| < 1).","O erro-padrão de UR é menor que o módulo do coeficiente.") -> O erro-padrão de UR é maior que o módulo do próprio coeficiente (|t| < 1).
B18: ="Resposta: o Princípio da Parsimônia diz que, entre modelos com desempenho equivalente, deve-se preferir o mais simples. Incluir as "&C7&" variáveis sem critério (i) consome graus de liberdade (de "&D8&" para "&C8&") e reduz as observações por parâmetro de "&FIXED(D9,1,TRUE)&" para "&FIXED(C9,1,TRUE)&", alargando os intervalos de confiança e aumentando a incerteza da economia reportada em M&V; (ii) provoca sobreajuste: o R² sobe ("&FIXED(C10,4,TRUE)&" contra "&FIXED(D10,4,TRUE)&"), mas o R² ajustado cai ("&FIXED(C11,4,TRUE)&" contra "&FIXED(D11,4,TRUE)&"); (iii) introduz multicolinearidade (Temp × UR, r = "&FIXED('4.1a Correlação'!C26,2,TRUE)&"): o erro-padrão do coeficiente de Temp vai de "&FIXED(D14,3,TRUE)&" para "&FIXED(C14,3,TRUE)&" e o coeficiente da UR sai com sinal contrário à física; (iv) dificulta a auditoria da distribuidora e da ANEEL, pois o modelo perde interpretabilidade e um erro de medição em variável irrelevante contamina a linha de base." -> Resposta: o Princípio da Parsimônia diz que, entre modelos com desempenho equivalente, deve-se preferir o mais simples. Incluir as 7 variáveis sem critério (i) consome graus de liberdade (de 48 para 44) e reduz as observações por parâmetro de 13,0 para 6,5, alargando os intervalos de confiança e aumentando a incerteza da economia reportada em M&V; (ii) provoca sobreajuste: o R² sobe (0,9527 contra 0,9513), mas o R² ajustado cai (0,9451 contra 0,9483); (iii) introduz multicolinearidade (Temp × UR, r = 0,93): o erro-padrão do coeficiente de Temp vai de 0,108 para 0,266 e o coeficiente da UR sai com sinal contrário à física; (iv) dificulta a auditoria da distribuidora e da ANEEL, pois o modelo perde interpretabilidade e um erro de medição em variável irrelevante contamina a linha de base.

Sheet 4.1d Dependência Temp-UR
B2: Questão 4.1 (complemento) – Dependência entre temperatura e umidade relativa
B3: Pergunta: a UR pode ser tratada como função da Temp e eliminada do modelo? Testes: (1) regressão auxiliar UR = a + b·Temp; (2) comparação de modelos; (3) significância da parte da UR não explicada por Temp (UR⊥).
B5: Regressão auxiliar: UR = a + b·Temp
B6: Intercepto a | C6: =INTERCEPT('Ano 0 - Linha de Base'!$J$6:$J$57,'Ano 0 - Linha de Base'!$I$6:$I$57) -> 0.32386423
B7: Inclinação b (fração de UR por °C) | C7: =SLOPE('Ano 0 - Linha de Base'!$J$6:$J$57,'Ano 0 - Linha de Base'!$I$6:$I$57) -> 0.012752614
B8: r (Temp, UR) | C8: =CORREL('Ano 0 - Linha de Base'!$I$6:$I$57,'Ano 0 - Linha de Base'!$J$6:$J$57) -> 0.92547248
B9: R² (parcela da UR explicada pela Temp) | C9: =RSQ('Ano 0 - Linha de Base'!$J$6:$J$57,'Ano 0 - Linha de Base'!$I$6:$I$57) -> 0.8564993
B10: Erro-padrão da estimativa de UR | C10: =STEYX('Ano 0 - Linha de Base'!$J$6:$J$57,'Ano 0 - Linha de Base'!$I$6:$I$57) -> 0.02911479
B11: VIF par-a-par = 1/(1−R²) | C11: =1/(1-C9) -> 6.9686074
B13: Comparação de modelos
B14: Modelo | C14: R² | D14: R² ajustado | E14: RMSE (MWh) | F14: CV(RMSE)
B15: A – P1, P2, Temp | C15: =C34 -> 0.95131221 | D15: =C35 -> 0.94826922 | E15: =C36 -> 3.4559023 | F15: =C41 -> 0.013264461
B16: B – P1, P2, UR | C16: =C52 -> 0.8928694 | D16: =C53 -> 0.88617374 | E16: =C54 -> 5.126349 | F16: =C59 -> 0.019675978
B17: C – P1, P2, Temp + UR⊥ | C17: =C71 -> 0.95225851 | D17: =C72 -> 0.9481954 | E17: =C73 -> 3.4583672 | F17: =C78 -> 0.013273922
B19: p-valor de UR⊥ no modelo C | C19: =F68 -> 0.33938724
B20: UR⊥ acrescenta informação (p < α)? | C20: =IF(C19<alfa,"SIM","NÃO") -> NÃO
B21: Melhor modelo (maior R² ajustado) | C21: =INDEX(B15:B17,MATCH(MAX(D15:D17),D15:D17,0)) -> A – P1, P2, Temp
B23: ="Conclusão: a Temp explica "&FIXED(C9*100,1,TRUE)&" % da variação da UR (r = "&FIXED(C8,2,TRUE)&"; VIF par-a-par = "&FIXED(C11,1,TRUE)&"). Trocar Temp por UR muda o RMSE de "&FIXED(E15,3,TRUE)&" para "&FIXED(E16,3,TRUE)&" MWh; acrescentar a parte da UR não explicada pela Temp (UR⊥) tem p = "&FIXED(C19,3,TRUE)&" ("&IF(C20="SIM","significativa","não significativa")&"). Logo, a UR atua no consumo essencialmente através da Temp, e pode ser eliminada em favor dela. Ressalva: isto não prova que a UR não influencie o consumo, apenas que, nestes dados, seu efeito não se separa do da temperatura." -> Conclusão: a Temp explica 85,6 % da variação da UR (r = 0,93; VIF par-a-par = 7,0). Trocar Temp por UR muda o RMSE de 3,456 para 5,126 MWh; acrescentar a parte da UR não explicada pela Temp (UR⊥) tem p = 0,339 (não significativa). Logo, a UR atua no consumo essencialmente através da Temp, e pode ser eliminada em favor dela. Ressalva: isto não prova que a UR não influencie o consumo, apenas que, nestes dados, seu efeito não se separa do da temperatura.
B26: Modelo A – P1, P2, Temp (adotado)
B27: Termo | C27: Coeficiente | D27: Erro-padrão | E27: t-stat | F27: p-valor | G27: IC95% inf. | H27: IC95% sup. | I27: Decisão (p < α)
B28: Intercepto | C28: =INDEX(LINEST('Ano 0 - Linha de Base'!$C$6:$C$57,Aux_X!$T$7:$V$58,TRUE(),TRUE()),1,4) -> 111.00555 | D28: =INDEX(LINEST('Ano 0 - Linha de Base'!$C$6:$C$57,Aux_X!$T$7:$V$58,TRUE(),TRUE()),2,4) -> 8.2075007 | E28: =C28/D28 -> 13.52489 | F28: =TDIST(ABS(E28),$C$38,2) -> 5.4199888e-18 | G28: =C28-TINV(alfa,$C$38)*D28 -> 94.503261 | H28: =C28+TINV(alfa,$C$38)*D28 -> 127.50783 | I28: —
B29: P1 (mil unid) | C29: =INDEX(LINEST('Ano 0 - Linha de Base'!$C$6:$C$57,Aux_X!$T$7:$V$58,TRUE(),TRUE()),1,3) -> 2.6082654 | D29: =INDEX(LINEST('Ano 0 - Linha de Base'!$C$6:$C$57,Aux_X!$T$7:$V$58,TRUE(),TRUE()),2,3) -> 0.18723287 | E29: =C29/D29 -> 13.930596 | F29: =TDIST(ABS(E29),$C$38,2) -> 1.7398016e-18 | G29: =C29-TINV(alfa,$C$38)*D29 -> 2.2318085 | H29: =C29+TINV(alfa,$C$38)*D29 -> 2.9847223 | I29: =IF(F29<alfa,"Significativa","Não significativa") -> Significativa
B30: P2 (mil unid) | C30: =INDEX(LINEST('Ano 0 - Linha de Base'!$C$6:$C$57,Aux_X!$T$7:$V$58,TRUE(),TRUE()),1,2) -> 1.4109802 | D30: =INDEX(LINEST('Ano 0 - Linha de Base'!$C$6:$C$57,Aux_X!$T$7:$V$58,TRUE(),TRUE()),2,2) -> 0.20466593 | E30: =C30/D30 -> 6.8940649 | F30: =TDIST(ABS(E30),$C$38,2) -> 1.0688158e-08 | G30: =C30-TINV(alfa,$C$38)*D30 -> 0.99947177 | H30: =C30+TINV(alfa,$C$38)*D30 -> 1.8224886 | I30: =IF(F30<alfa,"Significativa","Não significativa") -> Significativa
B31: Temp (°C) | C31: =INDEX(LINEST('Ano 0 - Linha de Base'!$C$6:$C$57,Aux_X!$T$7:$V$58,TRUE(),TRUE()),1,1) -> 1.7383993 | D31: =INDEX(LINEST('Ano 0 - Linha de Base'!$C$6:$C$57,Aux_X!$T$7:$V$58,TRUE(),TRUE()),2,1) -> 0.10764499 | E31: =C31/D31 -> 16.149375 | F31: =TDIST(ABS(E31),$C$38,2) -> 4.916028e-21 | G31: =C31-TINV(alfa,$C$38)*D31 -> 1.5219646 | H31: =C31+TINV(alfa,$C$38)*D31 -> 1.9548341 | I31: =IF(F31<alfa,"Significativa","Não significativa") -> Significativa
B33: Estatísticas do modelo
B34: R² | C34: =INDEX(LINEST('Ano 0 - Linha de Base'!$C$6:$C$57,Aux_X!$T$7:$V$58,TRUE(),TRUE()),3,1) -> 0.95131221
B35: R² ajustado | C35: =1-(1-C34)*(COUNT('Ano 0 - Linha de Base'!$C$6:$C$57)-1)/C38 -> 0.94826922
B36: Erro-padrão da regressão, RMSE (MWh) | C36: =INDEX(LINEST('Ano 0 - Linha de Base'!$C$6:$C$57,Aux_X!$T$7:$V$58,TRUE(),TRUE()),3,2) -> 3.4559023
B37: Estatística F | C37: =INDEX(LINEST('Ano 0 - Linha de Base'!$C$6:$C$57,Aux_X!$T$7:$V$58,TRUE(),TRUE()),4,1) -> 312.62446
B38: Graus de liberdade (n−k−1) | C38: =INDEX(LINEST('Ano 0 - Linha de Base'!$C$6:$C$57,Aux_X!$T$7:$V$58,TRUE(),TRUE()),4,2) -> 48
B39: SQ regressão | C39: =INDEX(LINEST('Ano 0 - Linha de Base'!$C$6:$C$57,Aux_X!$T$7:$V$58,TRUE(),TRUE()),5,1) -> 11201.267
B40: SQ resíduo | C40: =INDEX(LINEST('Ano 0 - Linha de Base'!$C$6:$C$57,Aux_X!$T$7:$V$58,TRUE(),TRUE()),5,2) -> 573.27653
B41: CV(RMSE) | C41: =C36/AVERAGE('Ano 0 - Linha de Base'!$C$6:$C$57) -> 0.013264461
B44: Modelo B – troca Temp por UR: P1, P2, UR
B45: Termo | C45: Coeficiente | D45: Erro-padrão | E45: t-stat | F45: p-valor | G45: IC95% inf. | H45: IC95% sup. | I45: Decisão (p < α)
B46: Intercepto | C46: =INDEX(LINEST('Ano 0 - Linha de Base'!$C$6:$C$57,Aux_X!$AC$7:$AE$58,TRUE(),TRUE()),1,4) -> 60.420288 | D46: =INDEX(LINEST('Ano 0 - Linha de Base'!$C$6:$C$57,Aux_X!$AC$7:$AE$58,TRUE(),TRUE()),2,4) -> 11.3949 | E46: =C46/D46 -> 5.3023974 | F46: =TDIST(ABS(E46),$C$56,2) -> 2.8575373e-06 | G46: =C46-TINV(alfa,$C$56)*D46 -> 37.509306 | H46: =C46+TINV(alfa,$C$56)*D46 -> 83.33127 | I46: —
B47: P1 (mil unid) | C47: =INDEX(LINEST('Ano 0 - Linha de Base'!$C$6:$C$57,Aux_X!$AC$7:$AE$58,TRUE(),TRUE()),1,3) -> 2.7331637 | D47: =INDEX(LINEST('Ano 0 - Linha de Base'!$C$6:$C$57,Aux_X!$AC$7:$AE$58,TRUE(),TRUE()),2,3) -> 0.27689297 | E47: =C47/D47 -> 9.870831 | F47: =TDIST(ABS(E47),$C$56,2) -> 3.8699901e-13 | G47: =C47-TINV(alfa,$C$56)*D47 -> 2.1764331 | H47: =C47+TINV(alfa,$C$56)*D47 -> 3.2898943 | I47: =IF(F47<alfa,"Significativa","Não significativa") -> Significativa
B48: P2 (mil unid) | C48: =INDEX(LINEST('Ano 0 - Linha de Base'!$C$6:$C$57,Aux_X!$AC$7:$AE$58,TRUE(),TRUE()),1,2) -> 2.0610031 | D48: =INDEX(LINEST('Ano 0 - Linha de Base'!$C$6:$C$57,Aux_X!$AC$7:$AE$58,TRUE(),TRUE()),2,2) -> 0.28083486 | E48: =C48/D48 -> 7.3388436 | F48: =TDIST(ABS(E48),$C$56,2) -> 2.2275894e-09 | G48: =C48-TINV(alfa,$C$56)*D48 -> 1.4963468 | H48: =C48+TINV(alfa,$C$56)*D48 -> 2.6256595 | I48: =IF(F48<alfa,"Significativa","Não significativa") -> Significativa
B49: UR (fração) | C49: =INDEX(LINEST('Ano 0 - Linha de Base'!$C$6:$C$57,Aux_X!$AC$7:$AE$58,TRUE(),TRUE()),1,1) -> 103.31382 | D49: =INDEX(LINEST('Ano 0 - Linha de Base'!$C$6:$C$57,Aux_X!$AC$7:$AE$58,TRUE(),TRUE()),2,1) -> 10.751256 | E49: =C49/D49 -> 9.6094652 | F49: =TDIST(ABS(E49),$C$56,2) -> 9.1800081e-13 | G49: =C49-TINV(alfa,$C$56)*D49 -> 81.69697 | H49: =C49+TINV(alfa,$C$56)*D49 -> 124.93067 | I49: =IF(F49<alfa,"Significativa","Não significativa") -> Significativa
B51: Estatísticas do modelo
...

Sheet 4.2a Regressão Completa
B2: Questão 4.2.a – Regressão Linear Múltipla (Ano 0) com as 7 variáveis
B3: Memória de cálculo: =INDEX(LINEST(EE; X; VERDADEIRO; VERDADEIRO); linha; coluna). Equivale à ferramenta "Regressão" do Excel.
B5: Modelo M1 – todas as variáveis
B6: Termo | C6: Coeficiente | D6: Erro-padrão | E6: t-stat | F6: p-valor | G6: IC95% inf. | H6: IC95% sup. | I6: Decisão (p < α)
B7: Intercepto | C7: =INDEX(LINEST('Ano 0 - Linha de Base'!$C$6:$C$57,'Ano 0 - Linha de Base'!$D$6:$J$57,TRUE(),TRUE()),1,8) -> 116.86469 | D7: =INDEX(LINEST('Ano 0 - Linha de Base'!$C$6:$C$57,'Ano 0 - Linha de Base'!$D$6:$J$57,TRUE(),TRUE()),2,8) -> 20.029942 | E7: =C7/D7 -> 5.8344997 | F7: =TDIST(ABS(E7),$C$21,2) -> 5.9052451e-07 | G7: =C7-TINV(alfa,$C$21)*D7 -> 76.496996 | H7: =C7+TINV(alfa,$C$21)*D7 -> 157.23239 | I7: —
B8: P1 (mil unid) – Estrutural Pesada | C8: =INDEX(LINEST('Ano 0 - Linha de Base'!$C$6:$C$57,'Ano 0 - Linha de Base'!$D$6:$J$57,TRUE(),TRUE()),1,7) -> 2.587412 | D8: =INDEX(LINEST('Ano 0 - Linha de Base'!$C$6:$C$57,'Ano 0 - Linha de Base'!$D$6:$J$57,TRUE(),TRUE()),2,7) -> 0.20384555 | E8: =C8/D8 -> 12.693002 | F8: =TDIST(ABS(E8),$C$21,2) -> 2.628911e-16 | G8: =C8-TINV(alfa,$C$21)*D8 -> 2.1765883 | H8: =C8+TINV(alfa,$C$21)*D8 -> 2.9982357 | I8: =IF(F8<alfa,"Significativa","Não significativa") -> Significativa
B9: P2 (mil unid) – Média | C9: =INDEX(LINEST('Ano 0 - Linha de Base'!$C$6:$C$57,'Ano 0 - Linha de Base'!$D$6:$J$57,TRUE(),TRUE()),1,6) -> 1.3549386 | D9: =INDEX(LINEST('Ano 0 - Linha de Base'!$C$6:$C$57,'Ano 0 - Linha de Base'!$D$6:$J$57,TRUE(),TRUE()),2,6) -> 0.22458475 | E9: =C9/D9 -> 6.0330839 | F9: =TDIST(ABS(E9),$C$21,2) -> 3.0172276e-07 | G9: =C9-TINV(alfa,$C$21)*D9 -> 0.90231781 | H9: =C9+TINV(alfa,$C$21)*D9 -> 1.8075595 | I9: =IF(F9<alfa,"Significativa","Não significativa") -> Significativa
B10: P3 (mil unid) – Leve | C10: =INDEX(LINEST('Ano 0 - Linha de Base'!$C$6:$C$57,'Ano 0 - Linha de Base'!$D$6:$J$57,TRUE(),TRUE()),1,5) -> -0.02567605 | D10: =INDEX(LINEST('Ano 0 - Linha de Base'!$C$6:$C$57,'Ano 0 - Linha de Base'!$D$6:$J$57,TRUE(),TRUE()),2,5) -> 0.15395214 | E10: =C10/D10 -> -0.16677943 | F10: =TDIST(ABS(E10),$C$21,2) -> 0.8683077 | G10: =C10-TINV(alfa,$C$21)*D10 -> -0.33594619 | H10: =C10+TINV(alfa,$C$21)*D10 -> 0.28459409 | I10: =IF(F10<alfa,"Significativa","Não significativa") -> Não significativa
B11: P4 (mil unid) – Inserções Poliméricas | C11: =INDEX(LINEST('Ano 0 - Linha de Base'!$C$6:$C$57,'Ano 0 - Linha de Base'!$D$6:$J$57,TRUE(),TRUE()),1,4) -> 0.29489058 | D11: =INDEX(LINEST('Ano 0 - Linha de Base'!$C$6:$C$57,'Ano 0 - Linha de Base'!$D$6:$J$57,TRUE(),TRUE()),2,4) -> 0.4983733 | E11: =C11/D11 -> 0.59170622 | F11: =TDIST(ABS(E11),$C$21,2) -> 0.5570755 | G11: =C11-TINV(alfa,$C$21)*D11 -> -0.7095148 | H11: =C11+TINV(alfa,$C$21)*D11 -> 1.299296 | I11: =IF(F11<alfa,"Significativa","Não significativa") -> Não significativa
B12: P5 (mil unid) – Acessórios | C12: =INDEX(LINEST('Ano 0 - Linha de Base'!$C$6:$C$57,'Ano 0 - Linha de Base'!$D$6:$J$57,TRUE(),TRUE()),1,3) -> 0.0034104952 | D12: =INDEX(LINEST('Ano 0 - Linha de Base'!$C$6:$C$57,'Ano 0 - Linha de Base'!$D$6:$J$57,TRUE(),TRUE()),2,3) -> 0.070346128 | E12: =C12/D12 -> 0.048481633 | F12: =TDIST(ABS(E12),$C$21,2) -> 0.9615518 | G12: =C12-TINV(alfa,$C$21)*D12 -> -0.13836281 | H12: =C12+TINV(alfa,$C$21)*D12 -> 0.1451838 | I12: =IF(F12<alfa,"Significativa","Não significativa") -> Não significativa
B13: Temp (°C) | C13: =INDEX(LINEST('Ano 0 - Linha de Base'!$C$6:$C$57,'Ano 0 - Linha de Base'!$D$6:$J$57,TRUE(),TRUE()),1,2) -> 1.9749882 | D13: =INDEX(LINEST('Ano 0 - Linha de Base'!$C$6:$C$57,'Ano 0 - Linha de Base'!$D$6:$J$57,TRUE(),TRUE()),2,2) -> 0.26612698 | E13: =C13/D13 -> 7.421225 | F13: =TDIST(ABS(E13),$C$21,2) -> 2.7719659e-09 | G13: =C13-TINV(alfa,$C$21)*D13 -> 1.4386445 | H13: =C13+TINV(alfa,$C$21)*D13 -> 2.5113319 | I13: =IF(F13<alfa,"Significativa","Não significativa") -> Significativa
B14: UR (fração) | C14: =INDEX(LINEST('Ano 0 - Linha de Base'!$C$6:$C$57,'Ano 0 - Linha de Base'!$D$6:$J$57,TRUE(),TRUE()),1,1) -> -17.112585 | D14: =INDEX(LINEST('Ano 0 - Linha de Base'!$C$6:$C$57,'Ano 0 - Linha de Base'!$D$6:$J$57,TRUE(),TRUE()),2,1) -> 18.12188 | E14: =C14/D14 -> -0.94430515 | F14: =TDIST(ABS(E14),$C$21,2) -> 0.35017047 | G14: =C14-TINV(alfa,$C$21)*D14 -> -53.634835 | H14: =C14+TINV(alfa,$C$21)*D14 -> 19.409665 | I14: =IF(F14<alfa,"Significativa","Não significativa") -> Não significativa
B16: Estatísticas do modelo
B17: R² | C17: =INDEX(LINEST('Ano 0 - Linha de Base'!$C$6:$C$57,'Ano 0 - Linha de Base'!$D$6:$J$57,TRUE(),TRUE()),3,1) -> 0.95266178
B18: R² ajustado | C18: =1-(1-C17)*(COUNT('Ano 0 - Linha de Base'!$C$6:$C$57)-1)/C21 -> 0.9451307
B19: Erro-padrão da regressão, RMSE (MWh) | C19: =INDEX(LINEST('Ano 0 - Linha de Base'!$C$6:$C$57,'Ano 0 - Linha de Base'!$D$6:$J$57,TRUE(),TRUE()),3,2) -> 3.5591938
B20: Estatística F | C20: =INDEX(LINEST('Ano 0 - Linha de Base'!$C$6:$C$57,'Ano 0 - Linha de Base'!$D$6:$J$57,TRUE(),TRUE()),4,1) -> 126.49737
B21: Graus de liberdade (n−k−1) | C21: =INDEX(LINEST('Ano 0 - Linha de Base'!$C$6:$C$57,'Ano 0 - Linha de Base'!$D$6:$J$57,TRUE(),TRUE()),4,2) -> 44
B22: SQ regressão | C22: =INDEX(LINEST('Ano 0 - Linha de Base'!$C$6:$C$57,'Ano 0 - Linha de Base'!$D$6:$J$57,TRUE(),TRUE()),5,1) -> 11217.157
B23: SQ resíduo | C23: =INDEX(LINEST('Ano 0 - Linha de Base'!$C$6:$C$57,'Ano 0 - Linha de Base'!$D$6:$J$57,TRUE(),TRUE()),5,2) -> 557.38588
B24: CV(RMSE) | C24: =C19/AVERAGE('Ano 0 - Linha de Base'!$C$6:$C$57) -> 0.013660915

Sheet 4.2b Filtragem
B2: Questão 4.2.b – Filtragem por significância (eliminação regressiva, critério p < α; α = 0,05 no Resumo)
B3: A cada iteração remove-se a variável de maior p-valor (se > α) e o modelo é reajustado. Para quando todas as variáveis forem significativas. A coluna "Consistência" confere se a variável removida saiu mesmo do bloco seguinte.
B5: Iteração 1 – 7 variáveis
B6: Termo | C6: Coeficiente | D6: Erro-padrão | E6: t-stat | F6: p-valor | G6: IC95% inf. | H6: IC95% sup. | I6: Decisão (p < α)
B7: Intercepto | C7: =INDEX(LINEST('Ano 0 - Linha de Base'!$C$6:$C$57,'Ano 0 - Linha de Base'!$D$6:$J$57,TRUE(),TRUE()),1,8) -> 116.86469 | D7: =INDEX(LINEST('Ano 0 - Linha de Base'!$C$6:$C$57,'Ano 0 - Linha de Base'!$D$6:$J$57,TRUE(),TRUE()),2,8) -> 20.029942 | E7: =C7/D7 -> 5.8344997 | F7: =TDIST(ABS(E7),$C$21,2) -> 5.9052451e-07 | G7: =C7-TINV(alfa,$C$21)*D7 -> 76.496996 | H7: =C7+TINV(alfa,$C$21)*D7 -> 157.23239 | I7: —
B8: P1 (mil unid) – Estrutural Pesada | C8: =INDEX(LINEST('Ano 0 - Linha de Base'!$C$6:$C$57,'Ano 0 - Linha de Base'!$D$6:$J$57,TRUE(),TRUE()),1,7) -> 2.587412 | D8: =INDEX(LINEST('Ano 0 - Linha de Base'!$C$6:$C$57,'Ano 0 - Linha de Base'!$D$6:$J$57,TRUE(),TRUE()),2,7) -> 0.20384555 | E8: =C8/D8 -> 12.693002 | F8: =TDIST(ABS(E8),$C$21,2) -> 2.628911e-16 | G8: =C8-TINV(alfa,$C$21)*D8 -> 2.1765883 | H8: =C8+TINV(alfa,$C$21)*D8 -> 2.9982357 | I8: =IF(F8<alfa,"Significativa","Não significativa") -> Significativa
B9: P2 (mil unid) – Média | C9: =INDEX(LINEST('Ano 0 - Linha de Base'!$C$6:$C$57,'Ano 0 - Linha de Base'!$D$6:$J$57,TRUE(),TRUE()),1,6) -> 1.3549386 | D9: =INDEX(LINEST('Ano 0 - Linha de Base'!$C$6:$C$57,'Ano 0 - Linha de Base'!$D$6:$J$57,TRUE(),TRUE()),2,6) -> 0.22458475 | E9: =C9/D9 -> 6.0330839 | F9: =TDIST(ABS(E9),$C$21,2) -> 3.0172276e-07 | G9: =C9-TINV(alfa,$C$21)*D9 -> 0.90231781 | H9: =C9+TINV(alfa,$C$21)*D9 -> 1.8075595 | I9: =IF(F9<alfa,"Significativa","Não significativa") -> Significativa
B10: P3 (mil unid) – Leve | C10: =INDEX(LINEST('Ano 0 - Linha de Base'!$C$6:$C$57,'Ano 0 - Linha de Base'!$D$6:$J$57,TRUE(),TRUE()),1,5) -> -0.02567605 | D10: =INDEX(LINEST('Ano 0 - Linha de Base'!$C$6:$C$57,'Ano 0 - Linha de Base'!$D$6:$J$57,TRUE(),TRUE()),2,5) -> 0.15395214 | E10: =C10/D10 -> -0.16677943 | F10: =TDIST(ABS(E10),$C$21,2) -> 0.8683077 | G10: =C10-TINV(alfa,$C$21)*D10 -> -0.33594619 | H10: =C10+TINV(alfa,$C$21)*D10 -> 0.28459409 | I10: =IF(F10<alfa,"Significativa","Não significativa") -> Não significativa
B11: P4 (mil unid) – Inserções Poliméricas | C11: =INDEX(LINEST('Ano 0 - Linha de Base'!$C$6:$C$57,'Ano 0 - Linha de Base'!$D$6:$J$57,TRUE(),TRUE()),1,4) -> 0.29489058 | D11: =INDEX(LINEST('Ano 0 - Linha de Base'!$C$6:$C$57,'Ano 0 - Linha de Base'!$D$6:$J$57,TRUE(),TRUE()),2,4) -> 0.4983733 | E11: =C11/D11 -> 0.59170622 | F11: =TDIST(ABS(E11),$C$21,2) -> 0.5570755 | G11: =C11-TINV(alfa,$C$21)*D11 -> -0.7095148 | H11: =C11+TINV(alfa,$C$21)*D11 -> 1.299296 | I11: =IF(F11<alfa,"Significativa","Não significativa") -> Não significativa
B12: P5 (mil unid) – Acessórios | C12: =INDEX(LINEST('Ano 0 - Linha de Base'!$C$6:$C$57,'Ano 0 - Linha de Base'!$D$6:$J$57,TRUE(),TRUE()),1,3) -> 0.0034104952 | D12: =INDEX(LINEST('Ano 0 - Linha de Base'!$C$6:$C$57,'Ano 0 - Linha de Base'!$D$6:$J$57,TRUE(),TRUE()),2,3) -> 0.070346128 | E12: =C12/D12 -> 0.048481633 | F12: =TDIST(ABS(E12),$C$21,2) -> 0.9615518 | G12: =C12-TINV(alfa,$C$21)*D12 -> -0.13836281 | H12: =C12+TINV(alfa,$C$21)*D12 -> 0.1451838 | I12: =IF(F12<alfa,"Significativa","Não significativa") -> Não significativa
B13: Temp (°C) | C13: =INDEX(LINEST('Ano 0 - Linha de Base'!$C$6:$C$57,'Ano 0 - Linha de Base'!$D$6:$J$57,TRUE(),TRUE()),1,2) -> 1.9749882 | D13: =INDEX(LINEST('Ano 0 - Linha de Base'!$C$6:$C$57,'Ano 0 - Linha de Base'!$D$6:$J$57,TRUE(),TRUE()),2,2) -> 0.26612698 | E13: =C13/D13 -> 7.421225 | F13: =TDIST(ABS(E13),$C$21,2) -> 2.7719659e-09 | G13: =C13-TINV(alfa,$C$21)*D13 -> 1.4386445 | H13: =C13+TINV(alfa,$C$21)*D13 -> 2.5113319 | I13: =IF(F13<alfa,"Significativa","Não significativa") -> Significativa
B14: UR (fração) | C14: =INDEX(LINEST('Ano 0 - Linha de Base'!$C$6:$C$57,'Ano 0 - Linha de Base'!$D$6:$J$57,TRUE(),TRUE()),1,1) -> -17.112585 | D14: =INDEX(LINEST('Ano 0 - Linha de Base'!$C$6:$C$57,'Ano 0 - Linha de Base'!$D$6:$J$57,TRUE(),TRUE()),2,1) -> 18.12188 | E14: =C14/D14 -> -0.94430515 | F14: =TDIST(ABS(E14),$C$21,2) -> 0.35017047 | G14: =C14-TINV(alfa,$C$21)*D14 -> -53.634835 | H14: =C14+TINV(alfa,$C$21)*D14 -> 19.409665 | I14: =IF(F14<alfa,"Significativa","Não significativa") -> Não significativa
B16: Estatísticas do modelo
B17: R² | C17: =INDEX(LINEST('Ano 0 - Linha de Base'!$C$6:$C$57,'Ano 0 - Linha de Base'!$D$6:$J$57,TRUE(),TRUE()),3,1) -> 0.95266178
B18: R² ajustado | C18: =1-(1-C17)*(COUNT('Ano 0 - Linha de Base'!$C$6:$C$57)-1)/C21 -> 0.9451307
B19: Erro-padrão da regressão, RMSE (MWh) | C19: =INDEX(LINEST('Ano 0 - Linha de Base'!$C$6:$C$57,'Ano 0 - Linha de Base'!$D$6:$J$57,TRUE(),TRUE()),3,2) -> 3.5591938
B20: Estatística F | C20: =INDEX(LINEST('Ano 0 - Linha de Base'!$C$6:$C$57,'Ano 0 - Linha de Base'!$D$6:$J$57,TRUE(),TRUE()),4,1) -> 126.49737
B21: Graus de liberdade (n−k−1) | C21: =INDEX(LINEST('Ano 0 - Linha de Base'!$C$6:$C$57,'Ano 0 - Linha de Base'!$D$6:$J$57,TRUE(),TRUE()),4,2) -> 44
B22: SQ regressão | C22: =INDEX(LINEST('Ano 0 - Linha de Base'!$C$6:$C$57,'Ano 0 - Linha de Base'!$D$6:$J$57,TRUE(),TRUE()),5,1) -> 11217.157
B23: SQ resíduo | C23: =INDEX(LINEST('Ano 0 - Linha de Base'!$C$6:$C$57,'Ano 0 - Linha de Base'!$D$6:$J$57,TRUE(),TRUE()),5,2) -> 557.38588
B24: CV(RMSE) | C24: =C19/AVERAGE('Ano 0 - Linha de Base'!$C$6:$C$57) -> 0.013660915
B27: Iteração 2 – sem P5
B28: Termo | C28: Coeficiente | D28: Erro-padrão | E28: t-stat | F28: p-valor | G28: IC95% inf. | H28: IC95% sup. | I28: Decisão (p < α)
B29: Intercepto | C29: =INDEX(LINEST('Ano 0 - Linha de Base'!$C$6:$C$57,Aux_X!$B$7:$G$58,TRUE(),TRUE()),1,7) -> 117.35587 | D29: =INDEX(LINEST('Ano 0 - Linha de Base'!$C$6:$C$57,Aux_X!$B$7:$G$58,TRUE(),TRUE()),2,7) -> 17.086141 | E29: =C29/D29 -> 6.8684835 | F29: =TDIST(ABS(E29),$C$42,2) -> 1.5970515e-08 | G29: =C29-TINV(alfa,$C$42)*D29 -> 82.942621 | H29: =C29+TINV(alfa,$C$42)*D29 -> 151.76913 | I29: —
B30: P1 (mil unid) – Estrutural Pesada | C30: =INDEX(LINEST('Ano 0 - Linha de Base'!$C$6:$C$57,Aux_X!$B$7:$G$58,TRUE(),TRUE()),1,6) -> 2.5899391 | D30: =INDEX(LINEST('Ano 0 - Linha de Base'!$C$6:$C$57,Aux_X!$B$7:$G$58,TRUE(),TRUE()),2,6) -> 0.19487177 | E30: =C30/D30 -> 13.290479 | F30: =TDIST(ABS(E30),$C$42,2) -> 3.4690893e-17 | G30: =C30-TINV(alfa,$C$42)*D30 -> 2.1974472 | H30: =C30+TINV(alfa,$C$42)*D30 -> 2.982431 | I30: =IF(F30<alfa,"Significativa","Não significativa") -> Significativa
B31: P2 (mil unid) – Média | C31: =INDEX(LINEST('Ano 0 - Linha de Base'!$C$6:$C$57,Aux_X!$B$7:$G$58,TRUE(),TRUE()),1,5) -> 1.3526469 | D31: =INDEX(LINEST('Ano 0 - Linha de Base'!$C$6:$C$57,Aux_X!$B$7:$G$58,TRUE(),TRUE()),2,5) -> 0.21710639 | E31: =C31/D31 -> 6.2303414 | F31: =TDIST(ABS(E31),$C$42,2) -> 1.4197839e-07 | G31: =C31-TINV(alfa,$C$42)*D31 -> 0.91537221 | H31: =C31+TINV(alfa,$C$42)*D31 -> 1.7899216 | I31: =IF(F31<alfa,"Significativa","Não significativa") -> Significativa
B32: P3 (mil unid) – Leve | C32: =INDEX(LINEST('Ano 0 - Linha de Base'!$C$6:$C$57,Aux_X!$B$7:$G$58,TRUE(),TRUE()),1,4) -> -0.026333388 | D32: =INDEX(LINEST('Ano 0 - Linha de Base'!$C$6:$C$57,Aux_X!$B$7:$G$58,TRUE(),TRUE()),2,4) -> 0.15164447 | E32: =C32/D32 -> -0.17365214 | F32: =TDIST(ABS(E32),$C$42,2) -> 0.86291767 | G32: =C32-TINV(alfa,$C$42)*D32 -> -0.33176103 | H32: =C32+TINV(alfa,$C$42)*D32 -> 0.27909426 | I32: =IF(F32<alfa,"Significativa","Não significativa") -> Não significativa
B33: P4 (mil unid) – Inserções Poliméricas | C33: =INDEX(LINEST('Ano 0 - Linha de Base'!$C$6:$C$57,Aux_X!$B$7:$G$58,TRUE(),TRUE()),1,3) -> 0.29377749 | D33: =INDEX(LINEST('Ano 0 - Linha de Base'!$C$6:$C$57,Aux_X!$B$7:$G$58,TRUE(),TRUE()),2,3) -> 0.49229465 | E33: =C33/D33 -> 0.59675134 | F33: =TDIST(ABS(E33),$C$42,2) -> 0.55366402 | G33: =C33-TINV(alfa,$C$42)*D33 -> -0.69775483 | H33: =C33+TINV(alfa,$C$42)*D33 -> 1.2853098 | I33: =IF(F33<alfa,"Significativa","Não significativa") -> Não significativa
B34: Temp (°C) | C34: =INDEX(LINEST('Ano 0 - Linha de Base'!$C$6:$C$57,Aux_X!$B$7:$G$58,TRUE(),TRUE()),1,2) -> 1.9759933 | D34: =INDEX(LINEST('Ano 0 - Linha de Base'!$C$6:$C$57,Aux_X!$B$7:$G$58,TRUE(),TRUE()),2,2) -> 0.26236075 | E34: =C34/D34 -> 7.5315887 | F34: =TDIST(ABS(E34),$C$42,2) -> 1.6705768e-09 | G34: =C34-TINV(alfa,$C$42)*D34 -> 1.4475716 | H34: =C34+TINV(alfa,$C$42)*D34 -> 2.504415 | I34: =IF(F34<alfa,"Significativa","Não significativa") -> Significativa
B35: UR (fração) | C35: =INDEX(LINEST('Ano 0 - Linha de Base'!$C$6:$C$57,Aux_X!$B$7:$G$58,TRUE(),TRUE()),1,1) -> -16.991321 | D35: =INDEX(LINEST('Ano 0 - Linha de Base'!$C$6:$C$57,Aux_X!$B$7:$G$58,TRUE(),TRUE()),2,1) -> 17.748363 | E35: =C35/D35 -> -0.95734582 | F35: =TDIST(ABS(E35),$C$42,2) -> 0.34350806 | G35: =C35-TINV(alfa,$C$42)*D35 -> -52.738359 | H35: =C35+TINV(alfa,$C$42)*D35 -> 18.755717 | I35: =IF(F35<alfa,"Significativa","Não significativa") -> Não significativa
B37: Estatísticas do modelo
B38: R² | C38: =INDEX(LINEST('Ano 0 - Linha de Base'!$C$6:$C$57,Aux_X!$B$7:$G$58,TRUE(),TRUE()),3,1) -> 0.95265925
B39: R² ajustado | C39: =1-(1-C38)*(COUNT('Ano 0 - Linha de Base'!$C$6:$C$57)-1)/C42 -> 0.94634715
B40: Erro-padrão da regressão, RMSE (MWh) | C40: =INDEX(LINEST('Ano 0 - Linha de Base'!$C$6:$C$57,Aux_X!$B$7:$G$58,TRUE(),TRUE()),3,2) -> 3.5195191
B41: Estatística F | C41: =INDEX(LINEST('Ano 0 - Linha de Base'!$C$6:$C$57,Aux_X!$B$7:$G$58,TRUE(),TRUE()),4,1) -> 150.92589
B42: Graus de liberdade (n−k−1) | C42: =INDEX(LINEST('Ano 0 - Linha de Base'!$C$6:$C$57,Aux_X!$B$7:$G$58,TRUE(),TRUE()),4,2) -> 45
B43: SQ regressão | C43: =INDEX(LINEST('Ano 0 - Linha de Base'!$C$6:$C$57,Aux_X!$B$7:$G$58,TRUE(),TRUE()),5,1) -> 11217.127
B44: SQ resíduo | C44: =INDEX(LINEST('Ano 0 - Linha de Base'!$C$6:$C$57,Aux_X!$B$7:$G$58,TRUE(),TRUE()),5,2) -> 557.41565
B45: CV(RMSE) | C45: =C40/AVERAGE('Ano 0 - Linha de Base'!$C$6:$C$57) -> 0.013508635
B48: Iteração 3 – sem P5, P3
...

Sheet 4.2c Modelo Final
B2: Questão 4.2.c – Equação da Linha de Base e validação PIMVP/PROPEE
B3: EE_LB = β0 + β1·P1 + β2·P2 + β3·Temp (variáveis que restaram da eliminação em 4.2b; coeficientes obtidos por LINEST sobre as semanas do Ano 0).
B5: Coeficientes do modelo final
B6: Termo | C6: Coeficiente | D6: Erro-padrão | E6: t-stat | F6: p-valor | G6: IC95% inf. | H6: IC95% sup. | I6: Decisão (p < α)
B7: Intercepto | C7: =INDEX(LINEST('Ano 0 - Linha de Base'!$C$6:$C$57,Aux_X!$T$7:$V$58,TRUE(),TRUE()),1,4) -> 111.00555 | D7: =INDEX(LINEST('Ano 0 - Linha de Base'!$C$6:$C$57,Aux_X!$T$7:$V$58,TRUE(),TRUE()),2,4) -> 8.2075007 | E7: =C7/D7 -> 13.52489 | F7: =TDIST(ABS(E7),$C$17,2) -> 5.4199888e-18 | G7: =C7-TINV(alfa,$C$17)*D7 -> 94.503261 | H7: =C7+TINV(alfa,$C$17)*D7 -> 127.50783 | I7: —
